<sdf version='1.7'>
  <world name='default'>
    <light name='sun' type='directional'>
      <cast_shadows>1</cast_shadows>
      <pose>0 0 10 0 -0 0</pose>
      <diffuse>0.8 0.8 0.8 1</diffuse>
      <specular>0.2 0.2 0.2 1</specular>
      <attenuation>
        <range>1000</range>
        <constant>0.9</constant>
        <linear>0.01</linear>
        <quadratic>0.001</quadratic>
      </attenuation>
      <direction>-0.5 0.1 -0.9</direction>
      <spot>
        <inner_angle>0</inner_angle>
        <outer_angle>0</outer_angle>
        <falloff>0</falloff>
      </spot>
    </light>
    <gravity>0 0 -9.8</gravity>
    <magnetic_field>6e-06 2.3e-05 -4.2e-05</magnetic_field>
    <atmosphere type='adiabatic'/>
    <physics name='default_physics' default='0' type='ode'>
      <max_step_size>0.001</max_step_size>
      <real_time_factor>1</real_time_factor>
      <real_time_update_rate>1000</real_time_update_rate>
    </physics>
    <scene>
      <ambient>0.4 0.4 0.4 1</ambient>
      <background>0.7 0.7 0.7 1</background>
      <shadows>1</shadows>
    </scene>
    <audio>
      <device>default</device>
    </audio>
    <wind/>
    <spherical_coordinates>
      <surface_model>EARTH_WGS84</surface_model>
      <latitude_deg>0</latitude_deg>
      <longitude_deg>0</longitude_deg>
      <elevation>0</elevation>
      <heading_deg>0</heading_deg>
    </spherical_coordinates>
    <model name='ground_plane'>
      <frame name='ground_plane::__model__' attached_to='ground_plane::link'>
        <pose relative_to='__model__'>0 0 0 0 -0 0</pose>
      </frame>
      <static>1</static>
      <link name='ground_plane::link'>
        <collision name='collision'>
          <geometry>
            <plane>
              <normal>0 0 1</normal>
              <size>100 100</size>
            </plane>
          </geometry>
          <surface>
            <contact>
              <collide_bitmask>65535</collide_bitmask>
              <ode/>
            </contact>
            <friction>
              <ode>
                <mu>100</mu>
                <mu2>50</mu2>
              </ode>
              <torsional>
                <ode/>
              </torsional>
            </friction>
            <bounce/>
          </surface>
          <max_contacts>10</max_contacts>
        </collision>
        <visual name='visual'>
          <cast_shadows>0</cast_shadows>
          <geometry>
            <plane>
              <normal>0 0 1</normal>
              <size>100 100</size>
            </plane>
          </geometry>
          <material>
            <script>
              <uri>file://media/materials/scripts/gazebo.material</uri>
              <name>Gazebo/Grey</name>
            </script>
          </material>
        </visual>
        <pose relative_to='ground_plane::__model__'>0 0 0 0 -0 0</pose>
        <self_collide>0</self_collide>
        <enable_wind>0</enable_wind>
        <kinematic>0</kinematic>
      </link>
    </model>
    <model name='table1'>
      <frame name='table::__model__' attached_to='table::link'>
        <pose relative_to='__model__'>0 0 0 0 -0 0</pose>
      </frame>
      <static>1</static>
      <link name='table::link'>
        <collision name='surface'>
          <pose>0 0 0.5 0 -0 0</pose>
          <geometry>
            <box>
              <size>1.5 0.8 0.03</size>
            </box>
          </geometry>
          <surface>
            <friction>
              <ode>
                <mu>0.6</mu>
                <mu2>0.6</mu2>
              </ode>
              <torsional>
                <ode/>
              </torsional>
            </friction>
            <contact>
              <ode/>
            </contact>
            <bounce/>
          </surface>
          <max_contacts>10</max_contacts>
        </collision>
        <visual name='visual1'>
          <pose>0 0 0.5 0 -0 0</pose>
          <geometry>
            <box>
              <size>1.5 0.8 0.03</size>
            </box>
          </geometry>
          <material>
            <script>
              <uri>file://media/materials/scripts/gazebo.material</uri>
              <name>Gazebo/Wood</name>
            </script>
          </material>
        </visual>
        <collision name='front_left_leg'>
          <pose>0.68 0.38 0.25 0 -0 0</pose>
          <geometry>
            <cylinder>
              <radius>0.02</radius>
              <length>0.5</length>
            </cylinder>
          </geometry>
          <max_contacts>10</max_contacts>
          <surface>
            <contact>
              <ode/>
            </contact>
            <bounce/>
            <friction>
              <torsional>
                <ode/>
              </torsional>
              <ode/>
            </friction>
          </surface>
        </collision>
        <visual name='front_left_leg'>
          <pose>0.68 0.38 0.25 0 -0 0</pose>
          <geometry>
            <cylinder>
              <radius>0.02</radius>
              <length>0.5</length>
            </cylinder>
          </geometry>
          <material>
            <script>
              <uri>file://media/materials/scripts/gazebo.material</uri>
              <name>Gazebo/Grey</name>
            </script>
          </material>
        </visual>
        <collision name='front_right_leg'>
          <pose>0.68 -0.38 0.25 0 -0 0</pose>
          <geometry>
            <cylinder>
              <radius>0.02</radius>
              <length>0.5</length>
            </cylinder>
          </geometry>
          <max_contacts>10</max_contacts>
          <surface>
            <contact>
              <ode/>
            </contact>
            <bounce/>
            <friction>
              <torsional>
                <ode/>
              </torsional>
              <ode/>
            </friction>
          </surface>
        </collision>
        <visual name='front_right_leg'>
          <pose>0.68 -0.38 0.25 0 -0 0</pose>
          <geometry>
            <cylinder>
              <radius>0.02</radius>
              <length>0.5</length>
            </cylinder>
          </geometry>
          <material>
            <script>
              <uri>file://media/materials/scripts/gazebo.material</uri>
              <name>Gazebo/Grey</name>
            </script>
          </material>
        </visual>
        <collision name='back_right_leg'>
          <pose>-0.68 -0.38 0.25 0 -0 0</pose>
          <geometry>
            <cylinder>
              <radius>0.02</radius>
              <length>0.5</length>
            </cylinder>
          </geometry>
          <max_contacts>10</max_contacts>
          <surface>
            <contact>
              <ode/>
            </contact>
            <bounce/>
            <friction>
              <torsional>
                <ode/>
              </torsional>
              <ode/>
            </friction>
          </surface>
        </collision>
        <visual name='back_right_leg'>
          <pose>-0.68 -0.38 0.25 0 -0 0</pose>
          <geometry>
            <cylinder>
              <radius>0.02</radius>
              <length>0.5</length>
            </cylinder>
          </geometry>
          <material>
            <script>
              <uri>file://media/materials/scripts/gazebo.material</uri>
              <name>Gazebo/Grey</name>
            </script>
          </material>
        </visual>
        <collision name='back_left_leg'>
          <pose>-0.68 0.38 0.25 0 -0 0</pose>
          <geometry>
            <cylinder>
              <radius>0.02</radius>
              <length>0.5</length>
            </cylinder>
          </geometry>
          <max_contacts>10</max_contacts>
          <surface>
            <contact>
              <ode/>
            </contact>
            <bounce/>
            <friction>
              <torsional>
                <ode/>
              </torsional>
              <ode/>
            </friction>
          </surface>
        </collision>
        <visual name='back_left_leg'>
          <pose>-0.68 0.38 0.25 0 -0 0</pose>
          <geometry>
            <cylinder>
              <radius>0.02</radius>
              <length>0.5</length>
            </cylinder>
          </geometry>
          <material>
            <script>
              <uri>file://media/materials/scripts/gazebo.material</uri>
              <name>Gazebo/Grey</name>
            </script>
          </material>
        </visual>
        <self_collide>0</self_collide>
        <enable_wind>0</enable_wind>
        <kinematic>0</kinematic>
        <pose relative_to='table::__model__'>0 0 0 0 -0 0</pose>
      </link>
      <pose>0.14 0 0 0 -0 1.57</pose>
      <static>1</static>
    </model>
    <model name='table2'>
      <frame name='table::__model__' attached_to='table::link'>
        <pose relative_to='__model__'>0 0 0 0 -0 0</pose>
      </frame>
      <static>1</static>
      <link name='table::link'>
        <collision name='surface'>
          <pose>0 0 0.5 0 -0 0</pose>
          <geometry>
            <box>
              <size>1.5 0.8 0.03</size>
            </box>
          </geometry>
          <surface>
            <friction>
              <ode>
                <mu>0.6</mu>
                <mu2>0.6</mu2>
              </ode>
              <torsional>
                <ode/>
              </torsional>
            </friction>
            <contact>
              <ode/>
            </contact>
            <bounce/>
          </surface>
          <max_contacts>10</max_contacts>
        </collision>
        <visual name='visual1'>
          <pose>0 0 0.5 0 -0 0</pose>
          <geometry>
            <box>
              <size>1.5 0.8 0.03</size>
            </box>
          </geometry>
          <material>
            <script>
              <uri>file://media/materials/scripts/gazebo.material</uri>
              <name>Gazebo/Wood</name>
            </script>
          </material>
        </visual>
        <collision name='front_left_leg'>
          <pose>0.68 0.38 0.25 0 -0 0</pose>
          <geometry>
            <cylinder>
              <radius>0.02</radius>
              <length>0.5</length>
            </cylinder>
          </geometry>
          <max_contacts>10</max_contacts>
          <surface>
            <contact>
              <ode/>
            </contact>
            <bounce/>
            <friction>
              <torsional>
                <ode/>
              </torsional>
              <ode/>
            </friction>
          </surface>
        </collision>
        <visual name='front_left_leg'>
          <pose>0.68 0.38 0.25 0 -0 0</pose>
          <geometry>
            <cylinder>
              <radius>0.02</radius>
              <length>0.5</length>
            </cylinder>
          </geometry>
          <material>
            <script>
              <uri>file://media/materials/scripts/gazebo.material</uri>
              <name>Gazebo/Grey</name>
            </script>
          </material>
        </visual>
        <collision name='front_right_leg'>
          <pose>0.68 -0.38 0.25 0 -0 0</pose>
          <geometry>
            <cylinder>
              <radius>0.02</radius>
              <length>0.5</length>
            </cylinder>
          </geometry>
          <max_contacts>10</max_contacts>
          <surface>
            <contact>
              <ode/>
            </contact>
            <bounce/>
            <friction>
              <torsional>
                <ode/>
              </torsional>
              <ode/>
            </friction>
          </surface>
        </collision>
        <visual name='front_right_leg'>
          <pose>0.68 -0.38 0.25 0 -0 0</pose>
          <geometry>
            <cylinder>
              <radius>0.02</radius>
              <length>0.5</length>
            </cylinder>
          </geometry>
          <material>
            <script>
              <uri>file://media/materials/scripts/gazebo.material</uri>
              <name>Gazebo/Grey</name>
            </script>
          </material>
        </visual>
        <collision name='back_right_leg'>
          <pose>-0.68 -0.38 0.25 0 -0 0</pose>
          <geometry>
            <cylinder>
              <radius>0.02</radius>
              <length>0.5</length>
            </cylinder>
          </geometry>
          <max_contacts>10</max_contacts>
          <surface>
            <contact>
              <ode/>
            </contact>
            <bounce/>
            <friction>
              <torsional>
                <ode/>
              </torsional>
              <ode/>
            </friction>
          </surface>
        </collision>
        <visual name='back_right_leg'>
          <pose>-0.68 -0.38 0.25 0 -0 0</pose>
          <geometry>
            <cylinder>
              <radius>0.02</radius>
              <length>0.5</length>
            </cylinder>
          </geometry>
          <material>
            <script>
              <uri>file://media/materials/scripts/gazebo.material</uri>
              <name>Gazebo/Grey</name>
            </script>
          </material>
        </visual>
        <collision name='back_left_leg'>
          <pose>-0.68 0.38 0.25 0 -0 0</pose>
          <geometry>
            <cylinder>
              <radius>0.02</radius>
              <length>0.5</length>
            </cylinder>
          </geometry>
          <max_contacts>10</max_contacts>
          <surface>
            <contact>
              <ode/>
            </contact>
            <bounce/>
            <friction>
              <torsional>
                <ode/>
              </torsional>
              <ode/>
            </friction>
          </surface>
        </collision>
        <visual name='back_left_leg'>
          <pose>-0.68 0.38 0.25 0 -0 0</pose>
          <geometry>
            <cylinder>
              <radius>0.02</radius>
              <length>0.5</length>
            </cylinder>
          </geometry>
          <material>
            <script>
              <uri>file://media/materials/scripts/gazebo.material</uri>
              <name>Gazebo/Grey</name>
            </script>
          </material>
        </visual>
        <self_collide>0</self_collide>
        <enable_wind>0</enable_wind>
        <kinematic>0</kinematic>
        <pose relative_to='table::__model__'>0 0 0 0 -0 0</pose>
      </link>
      <pose>0.94 0 0 0 -0 1.57</pose>
      <static>1</static>
    </model>
    <model name='unit_box'>
      <frame name='unit_box::__model__' attached_to='unit_box::link'>
        <pose relative_to='__model__'>0 0 0 0 -0 0</pose>
      </frame>
      <static>1</static>
      <link name='unit_box::link'>
        <inertial>
          <mass>1</mass>
          <inertia>
            <ixx>0.166667</ixx>
            <ixy>0</ixy>
            <ixz>0</ixz>
            <iyy>0.166667</iyy>
            <iyz>0</iyz>
            <izz>0.166667</izz>
          </inertia>
        </inertial>
        <visual name='visual'>
          <geometry>
            <box>
              <size>0.24 0.4 0.1</size>
            </box>
          </geometry>
          <material>
            <script>
              <name>Gazebo/Grey</name>
              <uri>file://media/materials/scripts/gazebo.material</uri>
            </script>
          </material>
        </visual>
        <collision name='visual'>
          <geometry>
            <box>
              <size>0.24 0.4 0.1</size>
            </box>
          </geometry>
          <max_contacts>10</max_contacts>
          <surface>
            <contact>
              <ode/>
            </contact>
            <bounce/>
            <friction>
              <torsional>
                <ode/>
              </torsional>
              <ode/>
            </friction>
          </surface>
        </collision>
        <self_collide>0</self_collide>
        <enable_wind>0</enable_wind>
        <kinematic>0</kinematic>
        <pose relative_to='unit_box::__model__'>0 0 0 0 -0 0</pose>
      </link>
      <pose>-0.14 0 0.565 0 -0 0</pose>
      <static>1</static>
    </model>
    <model name='BlueBin'>
      <frame name='Blue Bin::__model__' attached_to='Blue Bin::link'>
        <pose relative_to='__model__'>0 0 0 0 -0 0</pose>
      </frame>
      <static>1</static>
      <link name='Blue Bin::link'>
        <inertial>
          <mass>0.3</mass>
          <inertia>
            <ixx>0.00055575</ixx>
            <ixy>0</ixy>
            <ixz>0</ixz>
            <iyy>0.00055575</iyy>
            <iyz>0</iyz>
            <izz>0.0001755</izz>
          </inertia>
        </inertial>
        <collision name='collision'>
          <geometry>
            <mesh>
              <uri>model://binBlue/meshes/recycleBinBlue2.dae</uri>
              <scale>0.3 0.3 0.24</scale>
            </mesh>
          </geometry>
          <surface>
            <friction>
              <ode>
                <mu>3</mu>
                <mu2>3</mu2>
              </ode>
              <torsional>
                <ode/>
              </torsional>
            </friction>
            <contact>
              <ode>
                <kp>1e+07</kp>
                <kd>1</kd>
                <min_depth>0.001</min_depth>
                <max_vel>0.5</max_vel>
              </ode>
            </contact>
            <bounce/>
          </surface>
          <max_contacts>10</max_contacts>
        </collision>
        <visual name='visual'>
          <geometry>
            <mesh>
              <uri>model://binBlue/meshes/recycleBinBlue2.dae</uri>
              <scale>0.3 0.3 0.24</scale>
            </mesh>
          </geometry>
        </visual>
        <self_collide>0</self_collide>
        <enable_wind>0</enable_wind>
        <kinematic>0</kinematic>
        <pose relative_to='Blue Bin::__model__'>0 0 0 0 -0 0</pose>
      </link>
      <pose>-0.4652 -0.5 0 0 0 -1.57</pose>
      <static>1</static>
    </model>
    <model name='GreenBin'>
      <frame name='Green Bin::__model__' attached_to='Green Bin::link'>
        <pose relative_to='__model__'>0 0 0 0 -0 0</pose>
      </frame>
      <static>1</static>
      <link name='Green Bin::link'>
        <inertial>
          <mass>0.3</mass>
          <inertia>
            <ixx>0.00055575</ixx>
            <ixy>0</ixy>
            <ixz>0</ixz>
            <iyy>0.00055575</iyy>
            <iyz>0</iyz>
            <izz>0.0001755</izz>
          </inertia>
        </inertial>
        <collision name='collision'>
          <geometry>
            <mesh>
              <uri>model://binGreen/meshes/recycleBinGreen.dae</uri>
              <scale>0.3 0.3 0.24</scale>
            </mesh>
          </geometry>
          <surface>
            <friction>
              <ode>
                <mu>3</mu>
                <mu2>3</mu2>
              </ode>
              <torsional>
                <ode/>
              </torsional>
            </friction>
            <contact>
              <ode>
                <kp>1e+07</kp>
                <kd>1</kd>
                <min_depth>0.001</min_depth>
                <max_vel>0.5</max_vel>
              </ode>
            </contact>
            <bounce/>
          </surface>
          <max_contacts>10</max_contacts>
        </collision>
        <visual name='visual'>
          <geometry>
            <mesh>
              <uri>model://binGreen/meshes/recycleBinGreen.dae</uri>
              <scale>0.3 0.3 0.24</scale>
            </mesh>
          </geometry>
        </visual>
        <self_collide>0</self_collide>
        <enable_wind>0</enable_wind>
        <kinematic>0</kinematic>
        <pose relative_to='Green Bin::__model__'>0 0 0 0 -0 0</pose>
      </link>
      <pose>-0.4654 0.5 0 0 0 -1.57</pose>
      <static>1</static>
    </model>
    <model name='panda'>
      <joint name='world_joint' type='fixed'>
        <pose relative_to='__model__'>-0.1 0 0.615 0 -0 0</pose>
        <parent>world</parent>
        <child>panda_link0</child>
      </joint>
      <link name='panda_link0'>
        <pose relative_to='world_joint'>0 0 0 0 -0 0</pose>
        <inertial>
          <pose>-0.041018 -0.00014 0.049974 0 -0 0</pose>
          <mass>0.629769</mass>
          <inertia>
            <ixx>0.00315</ixx>
            <ixy>8.2904e-07</ixy>
            <ixz>0.00015</ixz>
            <iyy>0.00388</iyy>
            <iyz>8.2299e-06</iyz>
            <izz>0.004285</izz>
          </inertia>
        </inertial>
        <collision name='panda_link0_collision'>
          <pose>0 0 0 0 -0 0</pose>
          <geometry>
            <mesh>
              <scale>1 1 1</scale>
              <uri>/home/robot/ros/catkin_ws/src/franka_ros/franka_description/meshes/collision/link0.stl</uri>
            </mesh>
          </geometry>
          <max_contacts>10</max_contacts>
          <surface>
            <contact>
              <ode/>
            </contact>
            <bounce/>
            <friction>
              <torsional>
                <ode/>
              </torsional>
              <ode/>
            </friction>
          </surface>
        </collision>
        <visual name='panda_link0_visual'>
          <pose>0 0 0 0 -0 0</pose>
          <geometry>
            <mesh>
              <scale>1 1 1</scale>
              <uri>/home/robot/ros/catkin_ws/src/franka_ros/franka_description/meshes/visual/link0.dae</uri>
            </mesh>
          </geometry>
        </visual>
        <self_collide>1</self_collide>
        <enable_wind>0</enable_wind>
        <kinematic>0</kinematic>
      </link>
      <joint name='panda_joint1' type='revolute'>
        <pose relative_to='panda_link0'>0 0 0.333 0 -0 0</pose>
        <parent>panda_link0</parent>
        <child>panda_link1</child>
        <axis>
          <xyz>0 0 1</xyz>
          <limit>
            <lower>-2.8973</lower>
            <upper>2.8973</upper>
            <effort>87</effort>
            <velocity>2.175</velocity>
          </limit>
          <dynamics>
            <damping>0.003</damping>
            <friction>0</friction>
            <spring_reference>0</spring_reference>
            <spring_stiffness>0</spring_stiffness>
          </dynamics>
        </axis>
        <physics>
          <ode>
            <limit>
              <cfm>0</cfm>
              <erp>0.2</erp>
            </limit>
            <provide_feedback>1</provide_feedback>
          </ode>
          <provide_feedback>1</provide_feedback>
        </physics>
      </joint>
      <link name='panda_link1'>
        <pose relative_to='panda_joint1'>0 0 0 0 -0 0</pose>
        <inertial>
          <pose>0.003875 0.002081 -0.04762 0 -0 0</pose>
          <mass>4.97068</mass>
          <inertia>
            <ixx>0.70337</ixx>
            <ixy>-0.000139</ixy>
            <ixz>0.006772</ixz>
            <iyy>0.70661</iyy>
            <iyz>0.019169</iyz>
            <izz>0.009117</izz>
          </inertia>
        </inertial>
        <collision name='panda_link1_collision'>
          <pose>0 0 0 0 -0 0</pose>
          <geometry>
            <mesh>
              <scale>1 1 1</scale>
              <uri>/home/robot/ros/catkin_ws/src/franka_ros/franka_description/meshes/collision/link1.stl</uri>
            </mesh>
          </geometry>
          <max_contacts>10</max_contacts>
          <surface>
            <contact>
              <ode/>
            </contact>
            <bounce/>
            <friction>
              <torsional>
                <ode/>
              </torsional>
              <ode/>
            </friction>
          </surface>
        </collision>
        <visual name='panda_link1_visual'>
          <pose>0 0 0 0 -0 0</pose>
          <geometry>
            <mesh>
              <scale>1 1 1</scale>
              <uri>/home/robot/ros/catkin_ws/src/franka_ros/franka_description/meshes/visual/link1.dae</uri>
            </mesh>
          </geometry>
        </visual>
        <self_collide>1</self_collide>
        <enable_wind>0</enable_wind>
        <kinematic>0</kinematic>
      </link>
      <joint name='panda_joint2' type='revolute'>
        <pose relative_to='panda_link1'>0 0 0 -1.5708 0 0</pose>
        <parent>panda_link1</parent>
        <child>panda_link2</child>
        <axis>
          <xyz>0 0 1</xyz>
          <limit>
            <lower>-1.7628</lower>
            <upper>1.7628</upper>
            <effort>87</effort>
            <velocity>2.175</velocity>
          </limit>
          <dynamics>
            <damping>0.003</damping>
            <friction>0</friction>
            <spring_reference>0</spring_reference>
            <spring_stiffness>0</spring_stiffness>
          </dynamics>
        </axis>
        <physics>
          <ode>
            <limit>
              <cfm>0</cfm>
              <erp>0.2</erp>
            </limit>
            <provide_feedback>1</provide_feedback>
          </ode>
          <provide_feedback>1</provide_feedback>
        </physics>
      </joint>
      <link name='panda_link2'>
        <pose relative_to='panda_joint2'>0 0 0 0 -0 0</pose>
        <inertial>
          <pose>-0.003141 -0.02872 0.003495 0 -0 0</pose>
          <mass>0.646926</mass>
          <inertia>
            <ixx>0.007962</ixx>
            <ixy>-0.003925</ixy>
            <ixz>0.010254</ixz>
            <iyy>0.02811</iyy>
            <iyz>0.000704</iyz>
            <izz>0.025995</izz>
          </inertia>
        </inertial>
        <collision name='panda_link2_collision'>
          <pose>0 0 0 0 -0 0</pose>
          <geometry>
            <mesh>
              <scale>1 1 1</scale>
              <uri>/home/robot/ros/catkin_ws/src/franka_ros/franka_description/meshes/collision/link2.stl</uri>
            </mesh>
          </geometry>
          <max_contacts>10</max_contacts>
          <surface>
            <contact>
              <ode/>
            </contact>
            <bounce/>
            <friction>
              <torsional>
                <ode/>
              </torsional>
              <ode/>
            </friction>
          </surface>
        </collision>
        <visual name='panda_link2_visual'>
          <pose>0 0 0 0 -0 0</pose>
          <geometry>
            <mesh>
              <scale>1 1 1</scale>
              <uri>/home/robot/ros/catkin_ws/src/franka_ros/franka_description/meshes/visual/link2.dae</uri>
            </mesh>
          </geometry>
        </visual>
        <self_collide>1</self_collide>
        <enable_wind>0</enable_wind>
        <kinematic>0</kinematic>
      </link>
      <joint name='panda_joint3' type='revolute'>
        <pose relative_to='panda_link2'>0 -0.316 0 1.5708 -0 0</pose>
        <parent>panda_link2</parent>
        <child>panda_link3</child>
        <axis>
          <xyz>0 0 1</xyz>
          <limit>
            <lower>-2.8973</lower>
            <upper>2.8973</upper>
            <effort>87</effort>
            <velocity>2.175</velocity>
          </limit>
          <dynamics>
            <damping>0.003</damping>
            <friction>0</friction>
            <spring_reference>0</spring_reference>
            <spring_stiffness>0</spring_stiffness>
          </dynamics>
        </axis>
        <physics>
          <ode>
            <limit>
              <cfm>0</cfm>
              <erp>0.2</erp>
            </limit>
            <provide_feedback>1</provide_feedback>
          </ode>
          <provide_feedback>1</provide_feedback>
        </physics>
      </joint>
      <link name='panda_link3'>
        <pose relative_to='panda_joint3'>0 0 0 0 -0 0</pose>
        <inertial>
          <pose>0.027518 0.039252 -0.066502 0 -0 0</pose>
          <mass>3.2286</mass>
          <inertia>
            <ixx>0.037242</ixx>
            <ixy>-0.004761</ixy>
            <ixz>-0.011396</ixz>
            <iyy>0.036155</iyy>
            <iyz>-0.012805</iyz>
            <izz>0.01083</izz>
          </inertia>
        </inertial>
        <collision name='panda_link3_collision'>
          <pose>0 0 0 0 -0 0</pose>
          <geometry>
            <mesh>
              <scale>1 1 1</scale>
              <uri>/home/robot/ros/catkin_ws/src/franka_ros/franka_description/meshes/collision/link3.stl</uri>
            </mesh>
          </geometry>
          <max_contacts>10</max_contacts>
          <surface>
            <contact>
              <ode/>
            </contact>
            <bounce/>
            <friction>
              <torsional>
                <ode/>
              </torsional>
              <ode/>
            </friction>
          </surface>
        </collision>
        <visual name='panda_link3_visual'>
          <pose>0 0 0 0 -0 0</pose>
          <geometry>
            <mesh>
              <scale>1 1 1</scale>
              <uri>/home/robot/ros/catkin_ws/src/franka_ros/franka_description/meshes/visual/link3.dae</uri>
            </mesh>
          </geometry>
        </visual>
        <self_collide>1</self_collide>
        <enable_wind>0</enable_wind>
        <kinematic>0</kinematic>
      </link>
      <joint name='panda_joint4' type='revolute'>
        <pose relative_to='panda_link3'>0.0825 0 0 1.5708 -0 0</pose>
        <parent>panda_link3</parent>
        <child>panda_link4</child>
        <axis>
          <xyz>0 0 1</xyz>
          <limit>
            <lower>-3.0718</lower>
            <upper>-0.0698</upper>
            <effort>87</effort>
            <velocity>2.175</velocity>
          </limit>
          <dynamics>
            <damping>0.003</damping>
            <friction>0</friction>
            <spring_reference>0</spring_reference>
            <spring_stiffness>0</spring_stiffness>
          </dynamics>
        </axis>
        <physics>
          <ode>
            <limit>
              <cfm>0</cfm>
              <erp>0.2</erp>
            </limit>
            <provide_feedback>1</provide_feedback>
          </ode>
          <provide_feedback>1</provide_feedback>
        </physics>
      </joint>
      <link name='panda_link4'>
        <pose relative_to='panda_joint4'>0 0 0 0 -0 0</pose>
        <inertial>
          <pose>-0.05317 0.104419 0.027454 0 -0 0</pose>
          <mass>3.5879</mass>
          <inertia>
            <ixx>0.025853</ixx>
            <ixy>0.007796</ixy>
            <ixz>-0.001332</ixz>
            <iyy>0.019552</iyy>
            <iyz>0.008641</iyz>
            <izz>0.028323</izz>
          </inertia>
        </inertial>
        <collision name='panda_link4_collision'>
          <pose>0 0 0 0 -0 0</pose>
          <geometry>
            <mesh>
              <scale>1 1 1</scale>
              <uri>/home/robot/ros/catkin_ws/src/franka_ros/franka_description/meshes/collision/link4.stl</uri>
            </mesh>
          </geometry>
          <max_contacts>10</max_contacts>
          <surface>
            <contact>
              <ode/>
            </contact>
            <bounce/>
            <friction>
              <torsional>
                <ode/>
              </torsional>
              <ode/>
            </friction>
          </surface>
        </collision>
        <visual name='panda_link4_visual'>
          <pose>0 0 0 0 -0 0</pose>
          <geometry>
            <mesh>
              <scale>1 1 1</scale>
              <uri>/home/robot/ros/catkin_ws/src/franka_ros/franka_description/meshes/visual/link4.dae</uri>
            </mesh>
          </geometry>
        </visual>
        <self_collide>1</self_collide>
        <enable_wind>0</enable_wind>
        <kinematic>0</kinematic>
      </link>
      <joint name='panda_joint5' type='revolute'>
        <pose relative_to='panda_link4'>-0.0825 0.384 0 -1.5708 0 0</pose>
        <parent>panda_link4</parent>
        <child>panda_link5</child>
        <axis>
          <xyz>0 0 1</xyz>
          <limit>
            <lower>-2.8973</lower>
            <upper>2.8973</upper>
            <effort>12</effort>
            <velocity>2.61</velocity>
          </limit>
          <dynamics>
            <damping>0.003</damping>
            <friction>0</friction>
            <spring_reference>0</spring_reference>
            <spring_stiffness>0</spring_stiffness>
          </dynamics>
        </axis>
        <physics>
          <ode>
            <limit>
              <cfm>0</cfm>
              <erp>0.2</erp>
            </limit>
            <provide_feedback>1</provide_feedback>
          </ode>
          <provide_feedback>1</provide_feedback>
        </physics>
      </joint>
      <link name='panda_link5'>
        <pose relative_to='panda_joint5'>0 0 0 0 -0 0</pose>
        <inertial>
          <pose>-0.011953 0.041065 -0.038437 0 -0 0</pose>
          <mass>1.22595</mass>
          <inertia>
            <ixx>0.035549</ixx>
            <ixy>-0.002117</ixy>
            <ixz>-0.004037</ixz>
            <iyy>0.029474</iyy>
            <iyz>0.000229</iyz>
            <izz>0.008627</izz>
          </inertia>
        </inertial>
        <collision name='panda_link5_collision'>
          <pose>0 0 0 0 -0 0</pose>
          <geometry>
            <mesh>
              <scale>1 1 1</scale>
              <uri>/home/robot/ros/catkin_ws/src/franka_ros/franka_description/meshes/collision/link5.stl</uri>
            </mesh>
          </geometry>
          <max_contacts>10</max_contacts>
          <surface>
            <contact>
              <ode/>
            </contact>
            <bounce/>
            <friction>
              <torsional>
                <ode/>
              </torsional>
              <ode/>
            </friction>
          </surface>
        </collision>
        <visual name='panda_link5_visual'>
          <pose>0 0 0 0 -0 0</pose>
          <geometry>
            <mesh>
              <scale>1 1 1</scale>
              <uri>/home/robot/ros/catkin_ws/src/franka_ros/franka_description/meshes/visual/link5.dae</uri>
            </mesh>
          </geometry>
        </visual>
        <self_collide>1</self_collide>
        <enable_wind>0</enable_wind>
        <kinematic>0</kinematic>
      </link>
      <joint name='panda_joint6' type='revolute'>
        <pose relative_to='panda_link5'>0 0 0 1.5708 -0 0</pose>
        <parent>panda_link5</parent>
        <child>panda_link6</child>
        <axis>
          <xyz>0 0 1</xyz>
          <limit>
            <lower>-0.0175</lower>
            <upper>3.7525</upper>
            <effort>12</effort>
            <velocity>2.61</velocity>
          </limit>
          <dynamics>
            <damping>0.003</damping>
            <friction>0</friction>
            <spring_reference>0</spring_reference>
            <spring_stiffness>0</spring_stiffness>
          </dynamics>
        </axis>
        <physics>
          <ode>
            <limit>
              <cfm>0</cfm>
              <erp>0.2</erp>
            </limit>
            <provide_feedback>1</provide_feedback>
          </ode>
          <provide_feedback>1</provide_feedback>
        </physics>
      </joint>
      <link name='panda_link6'>
        <pose relative_to='panda_joint6'>0 0 0 0 -0 0</pose>
        <inertial>
          <pose>0.060149 -0.014117 -0.010517 0 -0 0</pose>
          <mass>1.66656</mass>
          <inertia>
            <ixx>0.001964</ixx>
            <ixy>0.000109</ixy>
            <ixz>-0.001158</ixz>
            <iyy>0.004354</iyy>
            <iyz>0.000341</iyz>
            <izz>0.005433</izz>
          </inertia>
        </inertial>
        <collision name='panda_link6_collision'>
          <pose>0 0 0 0 -0 0</pose>
          <geometry>
            <mesh>
              <scale>1 1 1</scale>
              <uri>/home/robot/ros/catkin_ws/src/franka_ros/franka_description/meshes/collision/link6.stl</uri>
            </mesh>
          </geometry>
          <max_contacts>10</max_contacts>
          <surface>
            <contact>
              <ode/>
            </contact>
            <bounce/>
            <friction>
              <torsional>
                <ode/>
              </torsional>
              <ode/>
            </friction>
          </surface>
        </collision>
        <visual name='panda_link6_visual'>
          <pose>0 0 0 0 -0 0</pose>
          <geometry>
            <mesh>
              <scale>1 1 1</scale>
              <uri>/home/robot/ros/catkin_ws/src/franka_ros/franka_description/meshes/visual/link6.dae</uri>
            </mesh>
          </geometry>
        </visual>
        <self_collide>1</self_collide>
        <enable_wind>0</enable_wind>
        <kinematic>0</kinematic>
      </link>
      <joint name='panda_joint7' type='revolute'>
        <pose relative_to='panda_link6'>0.088 0 0 1.5708 -0 0</pose>
        <parent>panda_link6</parent>
        <child>panda_link7</child>
        <axis>
          <xyz>0 0 1</xyz>
          <limit>
            <lower>-2.8973</lower>
            <upper>2.8973</upper>
            <effort>12</effort>
            <velocity>2.61</velocity>
          </limit>
          <dynamics>
            <damping>0.003</damping>
            <friction>0</friction>
            <spring_reference>0</spring_reference>
            <spring_stiffness>0</spring_stiffness>
          </dynamics>
        </axis>
        <physics>
          <ode>
            <limit>
              <cfm>0</cfm>
              <erp>0.2</erp>
            </limit>
            <provide_feedback>1</provide_feedback>
          </ode>
          <provide_feedback>1</provide_feedback>
        </physics>
      </joint>
      <link name='panda_link7'>
        <pose relative_to='panda_joint7'>0 0 0 0 -0 0</pose>
        <inertial>
          <pose>0.001758 0.001386 0.099157 0 -0 0</pose>
          <mass>1.46562</mass>
          <inertia>
            <ixx>0.0163963</ixx>
            <ixy>0.000395087</ixy>
            <ixz>-0.000710142</ixz>
            <iyy>0.0139736</iyy>
            <iyz>-0.00105378</iyz>
            <izz>0.00667566</izz>
          </inertia>
        </inertial>
        <collision name='panda_link7_collision'>
          <pose>0 0 0 0 -0 0</pose>
          <geometry>
            <mesh>
              <scale>1 1 1</scale>
              <uri>/home/robot/ros/catkin_ws/src/franka_ros/franka_description/meshes/collision/link7.stl</uri>
            </mesh>
          </geometry>
          <max_contacts>10</max_contacts>
          <surface>
            <contact>
              <ode/>
            </contact>
            <bounce/>
            <friction>
              <torsional>
                <ode/>
              </torsional>
              <ode/>
            </friction>
          </surface>
        </collision>
        <collision name='panda_link7_fixed_joint_lump__panda_hand_collision_1'>
          <pose>0 0 0.107 0 0 -0.785398</pose>
          <geometry>
            <mesh>
              <scale>1 1 1</scale>
              <uri>/home/robot/ros/catkin_ws/src/franka_ros/franka_description/meshes/collision/hand.stl</uri>
            </mesh>
          </geometry>
          <max_contacts>10</max_contacts>
          <surface>
            <contact>
              <ode/>
            </contact>
            <bounce/>
            <friction>
              <torsional>
                <ode/>
              </torsional>
              <ode/>
            </friction>
          </surface>
        </collision>
        <visual name='panda_link7_visual'>
          <pose>0 0 0 0 -0 0</pose>
          <geometry>
            <mesh>
              <scale>1 1 1</scale>
              <uri>/home/robot/ros/catkin_ws/src/franka_ros/franka_description/meshes/visual/link7.dae</uri>
            </mesh>
          </geometry>
        </visual>
        <visual name='panda_link7_fixed_joint_lump__panda_hand_visual_1'>
          <pose>0 0 0.107 0 0 -0.785398</pose>
          <geometry>
            <mesh>
              <scale>1 1 1</scale>
              <uri>/home/robot/ros/catkin_ws/src/franka_ros/franka_description/meshes/visual/hand.dae</uri>
            </mesh>
          </geometry>
        </visual>
        <visual name='panda_link7_fixed_joint_lump__camera_link_visual_2'>
          <pose>0.035355 -0.035355 0.107 0 -0 -0.785398</pose>
          <geometry>
            <box>
              <size>0.05 0.05 0.05</size>
            </box>
          </geometry>
        </visual>
        <sensor name='camera' type='depth'>
          <always_on>1</always_on>
          <visualize>1</visualize>
          <camera>
            <pose>0 0 0 0 -0 0</pose>
            <horizontal_fov>1.047</horizontal_fov>
            <image>
              <width>640</width>
              <height>480</height>
              <format>B8G8R8</format>
            </image>
            <depth_camera>
              <output>depths</output>
            </depth_camera>
            <clip>
              <near>0.1</near>
              <far>100</far>
            </clip>
          </camera>
          <plugin name='camera_controller' filename='libgazebo_ros_openni_kinect.so'>
            <baseline>0.2</baseline>
            <alwaysOn>1</alwaysOn>
            <updateRate>0.0</updateRate>
            <cameraName>camera</cameraName>
            <frameName>camera_depth_link</frameName>
            <imageTopicName>rgb/image_raw</imageTopicName>
            <depthImageTopicName>depth/image_raw</depthImageTopicName>
            <pointCloudTopicName>depth/points</pointCloudTopicName>
            <cameraInfoTopicName>rgb/camera_info</cameraInfoTopicName>
            <depthImageCameraInfoTopicName>depth/camera_info</depthImageCameraInfoTopicName>
            <pointCloudCutoff>0.4</pointCloudCutoff>
            <hackBaseline>0.07</hackBaseline>
            <distortionK1>0.0</distortionK1>
            <distortionK2>0.0</distortionK2>
            <distortionK3>0.0</distortionK3>
            <distortionT1>0.0</distortionT1>
            <distortionT2>0.0</distortionT2>
            <CxPrime>0.0</CxPrime>
            <Cx>0.0</Cx>
            <Cy>0.0</Cy>
            <focalLength>0.0</focalLength>
            <robotNamespace>/</robotNamespace>
          </plugin>
          <pose>0.035355 -0.035355 0.107 3.14159 -1.57079 -0.785397</pose>
        </sensor>
        <self_collide>1</self_collide>
        <enable_wind>0</enable_wind>
        <kinematic>0</kinematic>
      </link>
      <joint name='panda_finger_joint1' type='prismatic'>
        <pose relative_to='panda_link7'>0 0 0.1654 0 0 -0.785398</pose>
        <parent>panda_link7</parent>
        <child>panda_leftfinger</child>
        <axis>
          <xyz>0 1 0</xyz>
          <limit>
            <lower>0</lower>
            <upper>0.04</upper>
            <effort>100</effort>
            <velocity>0.2</velocity>
          </limit>
          <dynamics>
            <damping>0.3</damping>
            <friction>0</friction>
            <spring_reference>0</spring_reference>
            <spring_stiffness>0</spring_stiffness>
          </dynamics>
        </axis>
        <physics>
          <provide_feedback>1</provide_feedback>
          <ode>
            <limit>
              <cfm>0</cfm>
              <erp>0.2</erp>
            </limit>
            <provide_feedback>1</provide_feedback>
          </ode>
        </physics>
      </joint>
      <link name='panda_leftfinger'>
        <pose relative_to='panda_finger_joint1'>0 0 0 0 -0 0</pose>
        <inertial>
          <pose>0 0 0 0 -0 0</pose>
          <mass>0.015</mass>
          <inertia>
            <ixx>2.375e-06</ixx>
            <ixy>0</ixy>
            <ixz>0</ixz>
            <iyy>2.375e-06</iyy>
            <iyz>0</iyz>
            <izz>7.5e-07</izz>
          </inertia>
        </inertial>
        <collision name='panda_leftfinger_collision'>
          <pose>0 0.0185 0.011 0 -0 0</pose>
          <geometry>
            <box>
              <size>0.022 0.015 0.02</size>
            </box>
          </geometry>
          <max_contacts>10</max_contacts>
          <surface>
            <contact>
              <ode>
                <max_vel>0</max_vel>
                <min_depth>0.001</min_depth>
              </ode>
            </contact>
            <friction>
              <ode>
                <mu>1.13</mu>
                <mu2>1.13</mu2>
              </ode>
              <torsional>
                <ode/>
              </torsional>
            </friction>
            <bounce/>
          </surface>
        </collision>
        <collision name='panda_leftfinger_collision_1'>
          <pose>0 0.0068 0.0022 0 -0 0</pose>
          <geometry>
            <box>
              <size>0.022 0.0088 0.0038</size>
            </box>
          </geometry>
          <max_contacts>10</max_contacts>
          <surface>
            <contact>
              <ode>
                <max_vel>0</max_vel>
                <min_depth>0.001</min_depth>
              </ode>
            </contact>
            <friction>
              <ode>
                <mu>1.13</mu>
                <mu2>1.13</mu2>
              </ode>
              <torsional>
                <ode/>
              </torsional>
            </friction>
            <bounce/>
          </surface>
        </collision>
        <collision name='panda_leftfinger_collision_2'>
          <pose>0 0.0159 0.02835 0.523599 -0 0</pose>
          <geometry>
            <box>
              <size>0.0175 0.007 0.0235</size>
            </box>
          </geometry>
          <max_contacts>10</max_contacts>
          <surface>
            <contact>
              <ode>
                <max_vel>0</max_vel>
                <min_depth>0.001</min_depth>
              </ode>
            </contact>
            <friction>
              <ode>
                <mu>1.13</mu>
                <mu2>1.13</mu2>
              </ode>
              <torsional>
                <ode/>
              </torsional>
            </friction>
            <bounce/>
          </surface>
        </collision>
        <collision name='panda_leftfinger_collision_3'>
          <pose>0 0.00758 0.04525 0 -0 0</pose>
          <geometry>
            <box>
              <size>0.0175 0.0152 0.0185</size>
            </box>
          </geometry>
          <max_contacts>10</max_contacts>
          <surface>
            <contact>
              <ode>
                <max_vel>0</max_vel>
                <min_depth>0.001</min_depth>
              </ode>
            </contact>
            <friction>
              <ode>
                <mu>1.13</mu>
                <mu2>1.13</mu2>
              </ode>
              <torsional>
                <ode/>
              </torsional>
            </friction>
            <bounce/>
          </surface>
        </collision>
        <visual name='panda_leftfinger_visual'>
          <pose>0 0 0 0 -0 0</pose>
          <geometry>
            <mesh>
              <scale>1 1 1</scale>
              <uri>/home/robot/ros/catkin_ws/src/franka_ros/franka_description/meshes/visual/finger.dae</uri>
            </mesh>
          </geometry>
        </visual>
        <self_collide>1</self_collide>
        <enable_wind>0</enable_wind>
        <kinematic>0</kinematic>
      </link>
      <joint name='panda_finger_joint2' type='prismatic'>
        <pose relative_to='panda_link7'>0 0 0.1654 0 0 -0.785398</pose>
        <parent>panda_link7</parent>
        <child>panda_rightfinger</child>
        <axis>
          <xyz>0 -1 0</xyz>
          <limit>
            <lower>0</lower>
            <upper>0.04</upper>
            <effort>100</effort>
            <velocity>0.2</velocity>
          </limit>
          <dynamics>
            <damping>0.3</damping>
            <friction>0</friction>
            <spring_reference>0</spring_reference>
            <spring_stiffness>0</spring_stiffness>
          </dynamics>
        </axis>
        <physics>
          <provide_feedback>1</provide_feedback>
          <ode>
            <limit>
              <cfm>0</cfm>
              <erp>0.2</erp>
            </limit>
            <provide_feedback>1</provide_feedback>
          </ode>
        </physics>
      </joint>
      <link name='panda_rightfinger'>
        <pose relative_to='panda_finger_joint2'>0 0 0 0 -0 0</pose>
        <inertial>
          <pose>0 0 0 0 -0 0</pose>
          <mass>0.015</mass>
          <inertia>
            <ixx>2.375e-06</ixx>
            <ixy>0</ixy>
            <ixz>0</ixz>
            <iyy>2.375e-06</iyy>
            <iyz>0</iyz>
            <izz>7.5e-07</izz>
          </inertia>
        </inertial>
        <collision name='panda_rightfinger_collision'>
          <pose>0 -0.0185 0.011 0 -0 0</pose>
          <geometry>
            <box>
              <size>0.022 0.015 0.02</size>
            </box>
          </geometry>
          <max_contacts>10</max_contacts>
          <surface>
            <contact>
              <ode>
                <max_vel>0</max_vel>
                <min_depth>0.001</min_depth>
              </ode>
            </contact>
            <friction>
              <ode>
                <mu>1.13</mu>
                <mu2>1.13</mu2>
              </ode>
              <torsional>
                <ode/>
              </torsional>
            </friction>
            <bounce/>
          </surface>
        </collision>
        <collision name='panda_rightfinger_collision_1'>
          <pose>0 -0.0068 0.0022 0 -0 0</pose>
          <geometry>
            <box>
              <size>0.022 0.0088 0.0038</size>
            </box>
          </geometry>
          <max_contacts>10</max_contacts>
          <surface>
            <contact>
              <ode>
                <max_vel>0</max_vel>
                <min_depth>0.001</min_depth>
              </ode>
            </contact>
            <friction>
              <ode>
                <mu>1.13</mu>
                <mu2>1.13</mu2>
              </ode>
              <torsional>
                <ode/>
              </torsional>
            </friction>
            <bounce/>
          </surface>
        </collision>
        <collision name='panda_rightfinger_collision_2'>
          <pose>0 -0.0159 0.02835 -0.523599 0 0</pose>
          <geometry>
            <box>
              <size>0.0175 0.007 0.0235</size>
            </box>
          </geometry>
          <max_contacts>10</max_contacts>
          <surface>
            <contact>
              <ode>
                <max_vel>0</max_vel>
                <min_depth>0.001</min_depth>
              </ode>
            </contact>
            <friction>
              <ode>
                <mu>1.13</mu>
                <mu2>1.13</mu2>
              </ode>
              <torsional>
                <ode/>
              </torsional>
            </friction>
            <bounce/>
          </surface>
        </collision>
        <collision name='panda_rightfinger_collision_3'>
          <pose>0 -0.00758 0.04525 0 -0 0</pose>
          <geometry>
            <box>
              <size>0.0175 0.0152 0.0185</size>
            </box>
          </geometry>
          <max_contacts>10</max_contacts>
          <surface>
            <contact>
              <ode>
                <max_vel>0</max_vel>
                <min_depth>0.001</min_depth>
              </ode>
            </contact>
            <friction>
              <ode>
                <mu>1.13</mu>
                <mu2>1.13</mu2>
              </ode>
              <torsional>
                <ode/>
              </torsional>
            </friction>
            <bounce/>
          </surface>
        </collision>
        <visual name='panda_rightfinger_visual'>
          <pose>0 0 0 0 -0 3.14159</pose>
          <geometry>
            <mesh>
              <scale>1 1 1</scale>
              <uri>/home/robot/ros/catkin_ws/src/franka_ros/franka_description/meshes/visual/finger.dae</uri>
            </mesh>
          </geometry>
        </visual>
        <self_collide>1</self_collide>
        <enable_wind>0</enable_wind>
        <kinematic>0</kinematic>
      </link>
      <plugin name='gazebo_ros_control' filename='libgazebo_ros_control.so'>
        <controlPeriod>0.001</controlPeriod>
        <robotSimType>franka_gazebo/FrankaHWSim</robotSimType>
        <robotNamespace>/</robotNamespace>
      </plugin>
      <self_collide>1</self_collide>
      <static>0</static>
      <plugin name='gazebo_grasp_fix' filename='libgazebo_grasp_fix.so'>
        <arm>
          <arm_name>panda</arm_name>
          <palm_link>panda_link7</palm_link>
          <gripper_link>panda_leftfinger</gripper_link>
          <gripper_link>panda_rightfinger</gripper_link>
        </arm>
        <forces_angle_tolerance>100</forces_angle_tolerance>
        <update_rate>4</update_rate>
        <grip_count_threshold>4</grip_count_threshold>
        <max_grip_count>8</max_grip_count>
        <release_tolerance>0.005</release_tolerance>
        <disable_collisions_on_attach>0</disable_collisions_on_attach>
        <contact_topic>__default_topic__</contact_topic>
        <robotNamespace>/</robotNamespace>
      </plugin>
      <pose>0 0 0 0 -0 0</pose>
    </model>
    <model name='Apriltag36_11_00000'>
      <link name='main'>
        <pose>0 0 0 0 -0 0</pose>
        <visual name='main_Visual'>
          <geometry>
            <box>
              <size>0.999994 0.999994 0.010004</size>
            </box>
          </geometry>
          <material>
            <script>
              <uri>model://Apriltag36_11_00000/materials/scripts</uri>
              <uri>model://Apriltag36_11_00000/materials/textures</uri>
              <name>Apriltag36_11_00000</name>
            </script>
          </material>
        </visual>
        <self_collide>0</self_collide>
        <enable_wind>0</enable_wind>
        <kinematic>0</kinematic>
      </link>
      <static>1</static>
      <pose>0.849086 0.033278 0 0 -0 0</pose>
    </model>
    <state world_name='default'>
      <sim_time>672 925000000</sim_time>
      <real_time>0 0</real_time>
      <wall_time>1687872520 80653101</wall_time>
      <iterations>0</iterations>
      <model name='Apriltag36_11_00000'>
        <pose>0.46836 0.033278 0.528692 0 -0 0</pose>
        <scale>0.16674 0.16674 0.16674</scale>
        <link name='main'>
          <pose>0.46836 0.033278 0.528692 0 -0 0</pose>
          <velocity>0 0 0 0 -0 0</velocity>
          <acceleration>0 0 0 0 -0 0</acceleration>
          <wrench>0 0 0 0 -0 0</wrench>
        </link>
      </model>
      <model name='BlueBin'>
        <pose>-0.4652 -0.5 0 0 0 -1.57</pose>
        <scale>1 1 1</scale>
        <link name='Blue Bin::link'>
          <pose>-0.4652 -0.5 0 0 0 -1.57</pose>
          <velocity>0 0 0 0 -0 0</velocity>
          <acceleration>0 0 0 0 -0 0</acceleration>
          <wrench>0 0 0 0 -0 0</wrench>
        </link>
      </model>
      <model name='GreenBin'>
        <pose>-0.4654 0.5 0 0 0 -1.57</pose>
        <scale>1 1 1</scale>
        <link name='Green Bin::link'>
          <pose>-0.4654 0.5 0 0 0 -1.57</pose>
          <velocity>0 0 0 0 -0 0</velocity>
          <acceleration>0 0 0 0 -0 0</acceleration>
          <wrench>0 0 0 0 -0 0</wrench>
        </link>
      </model>
      <model name='ground_plane'>
        <pose>0 0 0 0 -0 0</pose>
        <scale>1 1 1</scale>
        <link name='ground_plane::link'>
          <pose>0 0 0 0 -0 0</pose>
          <velocity>0 0 0 0 -0 0</velocity>
          <acceleration>0 0 0 0 -0 0</acceleration>
          <wrench>0 0 0 0 -0 0</wrench>
        </link>
      </model>
      <model name='panda'>
        <pose>5e-05 -7e-05 2.8e-05 -0.000117 -7.9e-05 8e-06</pose>
        <scale>1 1 1</scale>
        <link name='panda_leftfinger'>
          <pose>0.220984 -0.026582 1.08677 2.56606 -0.683346 0.306627</pose>
          <velocity>-0.000583 -0.000115 -0.0001 -0.002512 0.003758 -0.002588</velocity>
          <acceleration>0 0 0 3e-06 3e-06 1e-06</acceleration>
          <wrench>0 0 0 0 -0 0</wrench>
        </link>
        <link name='panda_link0'>
          <pose>-0.099999 1e-06 0.61502 -0.000117 -7.9e-05 8e-06</pose>
          <velocity>-0.000784 0.000134 -0.000502 0.002853 0.01567 -3.6e-05</velocity>
          <acceleration>0 0 0 -2e-06 -0 -8e-06</acceleration>
          <wrench>0 0 0 0 -0 0</wrench>
        </link>
        <link name='panda_link1'>
          <pose>-0.100019 1.3e-05 0.948012 0.000143 -2.2e-05 2.73056</pose>
          <velocity>0.001093 -0.000375 0.000993 0.001545 0.000553 -0.004199</velocity>
          <acceleration>0 0 0 -3e-06 7e-06 -1e-06</acceleration>
          <wrench>0 0 0 0 -0 0</wrench>
        </link>
        <link name='panda_link2'>
          <pose>-0.10002 1.3e-05 0.948013 -1.57061 0.682393 2.73068</pose>
          <velocity>0.001041 -0.000377 0.000986 0.000413 -0.001237 -0.004238</velocity>
          <acceleration>0 0 0 6e-06 3e-06 0</acceleration>
          <wrench>0 0 0 0 -0 0</wrench>
        </link>
        <link name='panda_link3'>
          <pose>-0.282665 0.079675 1.19324 -0.370136 -0.587327 0.199689</pose>
          <velocity>2.8e-05 -0.00029 0.000757 -0.003146 -0.000189 0.002124</velocity>
          <acceleration>0 0 0 -3e-06 4e-06 -4e-06</acceleration>
          <wrench>0 0 0 0 -0 0</wrench>
        </link>
        <link name='panda_link4'>
          <pose>-0.215351 0.093299 1.23896 -0.617603 1.19247 -2.23547</pose>
          <velocity>-0.000236 -0.000226 0.000901 -0.002938 0.002393 0.000622</velocity>
          <acceleration>0 0 0 -1e-06 -2e-06 4e-06</acceleration>
          <wrench>0 0 0 0 -0 0</wrench>
        </link>
        <link name='panda_link5'>
          <pose>0.177321 0.086838 1.23349 1.96309 -0.977074 1.15918</pose>
          <velocity>-0.000255 0.00013 -0.000556 -0.005535 0.002785 0.001224</velocity>
          <acceleration>0 0 0 -2e-06 -6e-06 1.4e-05</acceleration>
          <wrench>0 0 0 0 -0 0</wrench>
        </link>
        <link name='panda_link6'>
          <pose>0.177323 0.086837 1.23348 2.24221 0.589877 -2.67408</pose>
          <velocity>-0.000145 0.000455 -0.000515 -0.005344 0.002936 0.001524</velocity>
          <acceleration>0 0 0 5e-06 -3e-06 1.3e-05</acceleration>
          <wrench>0 0 0 0 -0 0</wrench>
        </link>
        <link name='panda_link7'>
          <pose>0.112042 0.053881 1.18453 -2.91794 -0.840308 -0.788877</pose>
          <velocity>-0.00015 8.3e-05 0.000167 -0.003238 0.002151 -0.000568</velocity>
          <acceleration>0 0 0 3e-06 5e-06 1e-06</acceleration>
          <wrench>0 0 0 0 -0 0</wrench>
        </link>
        <link name='panda_rightfinger'>
          <pose>0.224506 0.016128 1.06682 2.56609 -0.683421 0.306415</pose>
          <velocity>-0.000599 -0.000181 -0.000233 -0.003388 0.004887 0.000735</velocity>
          <acceleration>0 0 0 9e-06 5e-06 6e-06</acceleration>
          <wrench>0 0 0 0 -0 0</wrench>
        </link>
      </model>
      <model name='table1'>
        <pose>0.14 0 0 0 -0 1.57</pose>
        <scale>1 1 1</scale>
        <link name='table::link'>
          <pose>0.14 0 0 0 -0 1.57</pose>
          <velocity>0 0 0 0 -0 0</velocity>
          <acceleration>0 0 0 0 -0 0</acceleration>
          <wrench>0 0 0 0 -0 0</wrench>
        </link>
      </model>
      <model name='table2'>
        <pose>0.933756 -0.00505 0 0 -0 1.57</pose>
        <scale>1 1 1</scale>
        <link name='table::link'>
          <pose>0.933756 -0.00505 0 0 -0 1.57</pose>
          <velocity>0 0 0 0 -0 0</velocity>
          <acceleration>0 0 0 0 -0 0</acceleration>
          <wrench>0 0 0 0 -0 0</wrench>
        </link>
      </model>
      <model name='unit_box'>
        <pose>-0.14 0 0.565 0 -0 0</pose>
        <scale>1 1 1</scale>
        <link name='unit_box::link'>
          <pose>-0.14 0 0.565 0 -0 0</pose>
          <velocity>0 0 0 0 -0 0</velocity>
          <acceleration>0 0 0 0 -0 0</acceleration>
          <wrench>0 0 0 0 -0 0</wrench>
        </link>
      </model>
      <light name='sun'>
        <pose>0 0 10 0 -0 0</pose>
      </light>
    </state>
    <gui fullscreen='0'>
      <camera name='user_camera'>
        <pose>-0.390909 -2.34767 2.12102 0 0.51164 1.0202</pose>
        <view_controller>orbit</view_controller>
        <projection_type>perspective</projection_type>
      </camera>
    </gui>
  </world>
</sdf>
